<?xml version="1.0" encoding="UTF-8"?>
<testng-results ignored="0" total="4" passed="1" failed="1" skipped="2">
  <reporter-output>
  </reporter-output>
  <suite started-at="2021-12-02T15:05:23 IST" name="Default suite" finished-at="2021-12-02T15:05:28 IST" duration-ms="4651">
    <groups>
    </groups>
    <test started-at="2021-12-02T15:05:23 IST" name="Default test" finished-at="2021-12-02T15:05:28 IST" duration-ms="4651">
      <class name="testngdemos.AsssertDemo">
        <test-method signature="startapp()[pri:0, instance:testngdemos.AsssertDemo@29647f75]" started-at="2021-12-02T15:05:23 IST" name="startapp" finished-at="2021-12-02T15:05:28 IST" duration-ms="4488" status="FAIL">
          <exception class="java.lang.AssertionError">
            <message>
              <![CDATA[expected [Demowebshop] but found [Demo Web Shop. Login]]]>
            </message>
            <full-stacktrace>
              <![CDATA[java.lang.AssertionError: expected [Demowebshop] but found [Demo Web Shop. Login]
at org.testng.Assert.fail(Assert.java:99)
at org.testng.Assert.failNotEquals(Assert.java:1037)
at org.testng.Assert.assertEqualsImpl(Assert.java:140)
at org.testng.Assert.assertEquals(Assert.java:122)
at org.testng.Assert.assertEquals(Assert.java:629)
at org.testng.Assert.assertEquals(Assert.java:639)
at testngdemos.AsssertDemo.startapp(AsssertDemo.java:26)
at java.base/jdk.internal.reflect.NativeMethodAccessorImpl.invoke0(Native Method)
at java.base/jdk.internal.reflect.NativeMethodAccessorImpl.invoke(NativeMethodAccessorImpl.java:62)
at java.base/jdk.internal.reflect.DelegatingMethodAccessorImpl.invoke(DelegatingMethodAccessorImpl.java:43)
at java.base/java.lang.reflect.Method.invoke(Method.java:566)
at org.testng.internal.MethodInvocationHelper.invokeMethod(MethodInvocationHelper.java:133)
at org.testng.internal.TestInvoker.invokeMethod(TestInvoker.java:598)
at org.testng.internal.TestInvoker.invokeTestMethod(TestInvoker.java:173)
at org.testng.internal.MethodRunner.runInSequence(MethodRunner.java:46)
at org.testng.internal.TestInvoker$MethodInvocationAgent.invoke(TestInvoker.java:824)
at org.testng.internal.TestInvoker.invokeTestMethods(TestInvoker.java:146)
at org.testng.internal.TestMethodWorker.invokeTestMethods(TestMethodWorker.java:146)
at org.testng.internal.TestMethodWorker.run(TestMethodWorker.java:128)
at java.base/java.util.ArrayList.forEach(ArrayList.java:1541)
at org.testng.TestRunner.privateRun(TestRunner.java:794)
at org.testng.TestRunner.run(TestRunner.java:596)
at org.testng.SuiteRunner.runTest(SuiteRunner.java:377)
at org.testng.SuiteRunner.runSequentially(SuiteRunner.java:371)
at org.testng.SuiteRunner.privateRun(SuiteRunner.java:332)
at org.testng.SuiteRunner.run(SuiteRunner.java:276)
at org.testng.SuiteRunnerWorker.runSuite(SuiteRunnerWorker.java:53)
at org.testng.SuiteRunnerWorker.run(SuiteRunnerWorker.java:96)
at org.testng.TestNG.runSuitesSequentially(TestNG.java:1212)
at org.testng.TestNG.runSuitesLocally(TestNG.java:1134)
at org.testng.TestNG.runSuites(TestNG.java:1063)
at org.testng.TestNG.run(TestNG.java:1031)
at org.testng.remote.AbstractRemoteTestNG.run(AbstractRemoteTestNG.java:115)
at org.testng.remote.RemoteTestNG.initAndRun(RemoteTestNG.java:251)
at org.testng.remote.RemoteTestNG.main(RemoteTestNG.java:77)
]]>
            </full-stacktrace>
          </exception> <!-- java.lang.AssertionError -->
          <reporter-output>
          </reporter-output>
        </test-method> <!-- startapp -->
        <test-method signature="loginapp()[pri:0, instance:testngdemos.AsssertDemo@29647f75]" started-at="2021-12-02T15:05:28 IST" name="loginapp" finished-at="2021-12-02T15:05:28 IST" depends-on-methods="testngdemos.AsssertDemo.startapp" duration-ms="0" status="SKIP">
          <exception class="java.lang.Throwable">
            <message>
              <![CDATA[Method AsssertDemo.loginapp()[pri:0, instance:testngdemos.AsssertDemo@29647f75] depends on not successfully finished methods]]>
            </message>
            <full-stacktrace>
              <![CDATA[java.lang.Throwable: Method AsssertDemo.loginapp()[pri:0, instance:testngdemos.AsssertDemo@29647f75] depends on not successfully finished methods
at org.testng.internal.TestInvoker.invokeTestMethods(TestInvoker.java:102)
at org.testng.internal.TestMethodWorker.invokeTestMethods(TestMethodWorker.java:146)
at org.testng.internal.TestMethodWorker.run(TestMethodWorker.java:128)
at java.base/java.util.ArrayList.forEach(ArrayList.java:1541)
at org.testng.TestRunner.privateRun(TestRunner.java:794)
at org.testng.TestRunner.run(TestRunner.java:596)
at org.testng.SuiteRunner.runTest(SuiteRunner.java:377)
at org.testng.SuiteRunner.runSequentially(SuiteRunner.java:371)
at org.testng.SuiteRunner.privateRun(SuiteRunner.java:332)
at org.testng.SuiteRunner.run(SuiteRunner.java:276)
at org.testng.SuiteRunnerWorker.runSuite(SuiteRunnerWorker.java:53)
at org.testng.SuiteRunnerWorker.run(SuiteRunnerWorker.java:96)
at org.testng.TestNG.runSuitesSequentially(TestNG.java:1212)
at org.testng.TestNG.runSuitesLocally(TestNG.java:1134)
at org.testng.TestNG.runSuites(TestNG.java:1063)
at org.testng.TestNG.run(TestNG.java:1031)
at org.testng.remote.AbstractRemoteTestNG.run(AbstractRemoteTestNG.java:115)
at org.testng.remote.RemoteTestNG.initAndRun(RemoteTestNG.java:251)
at org.testng.remote.RemoteTestNG.main(RemoteTestNG.java:77)
]]>
            </full-stacktrace>
          </exception> <!-- java.lang.Throwable -->
          <reporter-output>
          </reporter-output>
        </test-method> <!-- loginapp -->
        <test-method signature="signoff()[pri:0, instance:testngdemos.AsssertDemo@29647f75]" started-at="2021-12-02T15:05:28 IST" name="signoff" finished-at="2021-12-02T15:05:28 IST" depends-on-methods="testngdemos.AsssertDemo.loginapp" duration-ms="0" status="SKIP">
          <exception class="java.lang.Throwable">
            <message>
              <![CDATA[Method AsssertDemo.signoff()[pri:0, instance:testngdemos.AsssertDemo@29647f75] depends on not successfully finished methods]]>
            </message>
            <full-stacktrace>
              <![CDATA[java.lang.Throwable: Method AsssertDemo.signoff()[pri:0, instance:testngdemos.AsssertDemo@29647f75] depends on not successfully finished methods
at org.testng.internal.TestInvoker.invokeTestMethods(TestInvoker.java:102)
at org.testng.internal.TestMethodWorker.invokeTestMethods(TestMethodWorker.java:146)
at org.testng.internal.TestMethodWorker.run(TestMethodWorker.java:128)
at java.base/java.util.ArrayList.forEach(ArrayList.java:1541)
at org.testng.TestRunner.privateRun(TestRunner.java:794)
at org.testng.TestRunner.run(TestRunner.java:596)
at org.testng.SuiteRunner.runTest(SuiteRunner.java:377)
at org.testng.SuiteRunner.runSequentially(SuiteRunner.java:371)
at org.testng.SuiteRunner.privateRun(SuiteRunner.java:332)
at org.testng.SuiteRunner.run(SuiteRunner.java:276)
at org.testng.SuiteRunnerWorker.runSuite(SuiteRunnerWorker.java:53)
at org.testng.SuiteRunnerWorker.run(SuiteRunnerWorker.java:96)
at org.testng.TestNG.runSuitesSequentially(TestNG.java:1212)
at org.testng.TestNG.runSuitesLocally(TestNG.java:1134)
at org.testng.TestNG.runSuites(TestNG.java:1063)
at org.testng.TestNG.run(TestNG.java:1031)
at org.testng.remote.AbstractRemoteTestNG.run(AbstractRemoteTestNG.java:115)
at org.testng.remote.RemoteTestNG.initAndRun(RemoteTestNG.java:251)
at org.testng.remote.RemoteTestNG.main(RemoteTestNG.java:77)
]]>
            </full-stacktrace>
          </exception> <!-- java.lang.Throwable -->
          <reporter-output>
          </reporter-output>
        </test-method> <!-- signoff -->
        <test-method signature="closebrowser()[pri:0, instance:testngdemos.AsssertDemo@29647f75]" started-at="2021-12-02T15:05:28 IST" name="closebrowser" finished-at="2021-12-02T15:05:28 IST" depends-on-methods="testngdemos.AsssertDemo.signoff" duration-ms="105" status="PASS">
          <reporter-output>
          </reporter-output>
        </test-method> <!-- closebrowser -->
      </class> <!-- testngdemos.AsssertDemo -->
    </test> <!-- Default test -->
  </suite> <!-- Default suite -->
</testng-results>
